# 34.例外

如果我们的程序出现错误，我们希望能够以某种方式处理它。一种方法是通过*异常*。异常是我们试图在 try{}块中执行一些代码的机制，如果出现错误，就会抛出异常。然后，控制被转移到 catch 子句，该子句处理该异常。try/catch 块的结构应该是:

```
int main()
{
    try
    {
        // your code here
        // throw an exception if there is an error
    }
    catch (type_of_the_exception e)
    {
        // catch and handle the exception
    }
}

```

一个简单的 try/catch 示例是:

```
#include <iostream>

int main()
{
    try
    {
        std::cout << "Let's assume some error occurred in our program." << '\n';
        std::cout << "We throw an exception of type int, for example." << '\n';
        std::cout << "This signals that something went wrong." << '\n';
        throw 123;    // throw an exception if there is an error
    }
    catch (int e)
    {
        // catch and handle the exception
        std::cout << "Exception raised!." << '\n';
        std::cout << "The exception has a value of " << e <<  '\n';
    }
}

```

说明:这里我们尝试执行`try`块中的代码。如果出现错误，我们会抛出一个异常，表示出现了问题。我们例子中的异常是 int 类型的，但是它可以是任何类型的。当抛出异常时，控制被转移到一个`catch`子句，该子句处理异常。在我们的例子中，它处理类型`int`的异常。

我们可以抛出不同类型的异常，`std::string`例如:

```
#include <iostream>
#include <string>

int main()
{
    try
    {
        std::cout << "Let's assume some error occured in our program." << '\n';
        std::cout << "We throw an exception of type string

, for example." << '\n';
        std::cout << "This signals that something went wrong." << '\n';
        throw std::string{ "Some string error" };    // throw an exception // if there is an error
    }
    catch (const std::string& e)
    {
        // catch and handle the exception
        std::cout << "String exception raised!." << '\n';
        std::cout << "The exception has a value of: " << e << '\n';
    }

}

```

我们可以有/引发多个异常。它们可以是不同的类型。在这种情况下，我们有一个 try 和多个 catch 块。每个 catch 块处理不同的异常。

```
#include <iostream>
#include <string>

int main()
{
    try
    {
        throw 123;
        // the following will not execute as
        // the control has been transferred to a catch clause
        throw std::string{ "Some string error" };
    }
    catch (int e)
    {
        std::cout << "Integer exception raised! The value is " << e << '\n';
    }
    catch (const std::string& e)
    {
        // catch and handle the exception
        std::cout << "String exception raised!." << '\n';
        std::cout << "The exception has a value of: " << e << '\n';
    }
}

```

这里我们在 try 块中抛出了多个异常。第一个是`int`类型，第二个是`std::string`类型。当第一个异常被抛出时，程序的控制权被转移到一个 catch 子句。这意味着 try 块中的剩余代码将不会被执行。

更现实的情况是:

```
#include <iostream>
#include <string>

int main()
{
    try
    {
        bool someflag = true;
        bool someotherflag = true;
        std::cout << "We can have multiple throw exceptions." << '\n';
        if (someflag)
        {
            std::cout << "Throwing an int exception." << '\n';
            throw 123;
        }
        if(someotherflag)
        {
            std::cout << "Throwing a string exception." << '\n';
            throw std::string{ "Some string error" };
        }
    }
    catch (int e)
    {
        // catch and handle the exception
        std::cout << "Integer exception raised!." << '\n';
        std::cout << "The exception has a value of: " << e << '\n';
    }

    catch (const std::string& e)
    {
        // catch and handle the exception
        std::cout << "String exception raised!." << '\n';
        std::cout << "The exception has a value of: " << e << '\n';
    }
}

```

这里我们在 try 块中抛出了多个异常。出于说明的目的，它们依赖于一些条件。当遇到第一个异常时，控制被转移到适当的 catch 子句。