# 十七、异常处理

改进错误恢复是提高代码健壮性的最有效的方法之一。

不幸的是，忽略错误条件几乎是公认的做法，就好像我们对错误持否定态度一样。毫无疑问，一个原因是检查许多错误的繁琐和代码膨胀。例如，`printf()`返回成功打印的字符数，但是实际上没有人检查这个值。光是代码的激增就令人厌恶，更不用说阅读代码的难度了。

C 的错误处理方法的问题可以被认为是耦合——函数的用户必须将错误处理代码与该函数紧密地联系在一起，以至于它变得太笨拙而难以使用。

C++ 的主要特性之一是异常处理，这是思考和处理错误的一种更好的方式。异常处理有几个好处。

1.  编写错误处理代码并不那么乏味，也不会与您的“正常”代码混淆。你写下你希望 T1 发生的代码；稍后在一个单独的部分中，您将编写代码来处理这些问题。如果多次调用一个函数，就可以在一个地方一次性处理该函数的错误。
2.  错误不容忽视。如果一个函数需要向该函数的调用者发送一个错误消息，它会将一个表示该错误的对象“抛出”该函数。如果调用者没有“捕获”错误并处理它，它将进入下一个封闭的动态范围，依此类推，直到错误被捕获或者程序因为没有处理程序来捕获这种类型的异常而终止。

本章考察了 C 语言的错误处理方法，讨论了它为什么不适用于 C 语言，并解释了它为什么不适用于 C++。本章还涵盖了支持异常处理的 C++ 关键字`try`、`throw`和`catch`。

传统错误处理

在本书的大部分例子中，我按照预期使用了`assert()`:在开发过程中使用代码进行调试，这些代码可以在产品发布时用`#define NDEBUG`禁用。运行时错误检查使用在第 9 章的[中开发的`require.h`函数(`assure()`和`require()`)。这些函数是一种方便的表达方式，“这里有一个问题，你可能想用一些更复杂的代码来处理，但是在这个例子中你不需要被它分散注意力。”对于小程序来说，`require.h`函数可能已经足够了，但是对于复杂的产品来说，您可能想要编写更复杂的错误处理代码。](09.html)

当您确切地知道要做什么时，错误处理是非常简单的，因为您在该上下文中有所有必要的信息。您可以在这一点上处理错误。

当 *you* 在该上下文中没有足够的信息，并且需要将错误信息传递到存在该信息的不同上下文中时，问题就出现了。在 C 中，您可以使用三种方法来处理这种情况。

1.  从函数返回错误信息，或者，如果返回值不能这样使用，则设置一个全局错误条件标志。(标准 C 提供了`errno`和`perror()`来支持这个*。*)如上所述，程序员很可能会忽略错误信息，因为每个函数调用都必须进行冗长而令人困惑的错误检查。此外，从遇到异常情况的函数返回可能没有意义。
2.  使用鲜为人知的标准 C 库信号处理系统，用`signal()`函数(确定事件发生时会发生什么)和`raise()`(生成事件)实现。同样，这种方法涉及到高耦合，因为它要求生成信号的任何库的用户理解并安装适当的信号处理机制。在大型项目中，来自不同库的信号编号可能会冲突。
3.  使用标准 C 库中的非本地`goto`函数:`setjmp()`和`longjmp()`。用`setjmp()`你在程序中保存一个已知良好的状态，如果你遇到麻烦，`longjmp()`将恢复那个状态。同样，在存储状态的位置和发生错误的位置之间存在高度耦合。

当考虑 C++ 的错误处理方案时，还有一个额外的关键问题:signals 和`setjmp()` / `longjmp()`的 C 技术不调用析构函数，所以对象没有被适当地清理。(事实上，如果`longjmp()`跳过了应该调用析构函数的作用域的末尾，程序的行为就是未定义的*。*)这使得从异常情况中有效恢复变得几乎不可能，因为你总是会留下那些没有被清理并且不能再被访问的对象。清单 17-1 用`setjmp/longjmp`演示了这一点。

***[清单 17-1](#_list1)*** 。演示异常处理(用 C 的 setjmp() & longjmp())

```cpp
//: C17:Nonlocal.cpp
// setjmp() & longjmp().
#include <iostream>
#include <csetjmp>
using namespace std;
class Rainbow {
public:
  Rainbow() { cout << "Rainbow()" << endl; }
  ∼Rainbow() { cout << "∼Rainbow()" << endl; }
};
jmp_buf kansas;
void oz() {
  Rainbow rb;
  for(int i = 0; i< 3; i++)
    cout << "there's no place like home" << endl;
  longjmp(kansas, 47);
}
int main() {
  if(setjmp(kansas) == 0) {
    cout << "tornado, witch, munchkins..." << endl;
    oz();
  } else {
    cout << "Auntie Em! "
         << "I had the strangest dream..."
         << endl;
  }
} ///:∼
```

`setjmp()`函数很奇怪，因为如果你直接调用它，它会将当前处理器状态的所有相关信息(比如指令指针和运行时堆栈指针的内容)存储在`jmp_buf`中，并返回零。在这种情况下，它的行为就像一个普通的函数。然而，如果你用同一个`jmp_buf`呼叫`longjmp()`，就好像你又从`setjmp()`回来了——你正好从`setjmp()`的后端出来。这一次，返回值是`longjmp()`的第二个参数，因此您可以发现您实际上是从`longjmp()`返回的。你可以想象，有了许多不同的`jmp_buf`，你可以在程序中的许多不同的地方出现。本地`goto`(带标签)和非本地`goto`的区别在于，你可以用`setjmp()` / `longjmp()`返回到运行时栈中任何更高的预定位置(任何你调用了`setjmp()`的地方)。

C++ 的问题是`longjmp()`不尊重对象；特别是当它跳出一个作用域时，它不会调用析构函数。析构函数调用是必不可少的，所以这种方法不适用于 C++。事实上，C++ 标准规定，用`goto`分支到一个作用域(有效地绕过构造器调用)，或者用`longjmp()`分支到一个作用域之外，其中堆栈上的一个对象有一个析构函数，组合未定义的行为。

抛出异常

如果您在代码中遇到异常情况——也就是说，如果您在当前上下文中没有足够的信息来决定做什么——您可以通过创建一个包含该信息的对象并将它“抛出”当前上下文，将有关错误的信息发送到一个更大的上下文中。这被称为抛出异常。清单 17-2 展示了它的样子。

***[清单 17-2](#_list2)*** 。引发异常

```cpp
//: C17:MyError.cpp {RunByHand}
 classMyError {
 const char* const data;
public:
  MyError(const char* const msg = 0) : data(msg) {}
};
void f() {
  // Here we "throw" an exception object:
  throw MyError("something bad happened");
}
int main() {
  // As you’ll see shortly, we’ll want a "try block" here:
  f();
} ///:∼
```

`MyError`是一个普通的类，在这种情况下，它接受一个`char*`作为构造器参数。抛出时可以使用任何类型(包括内置类型)，但通常要为抛出异常创建特殊的类。

关键字`throw`导致了许多相对神奇的事情发生。首先，它创建一个你抛出的对象的副本，实际上，从包含抛出表达式的函数中“返回”它，即使该对象类型通常不是该函数要返回的类型。考虑异常处理的一个天真的方法是作为一个替代的返回机制(尽管你会发现如果你把这个类比得太远，你会陷入麻烦)。您还可以通过引发异常来退出普通范围。在任何情况下，都会返回一个值，并且函数或作用域会退出。

与`return`语句的任何相似之处都到此为止，因为返回的*与普通函数调用返回的地方完全不同。*

![image](img/sq.jpg) **注意**你会在代码的一个适当的部分结束——称为异常处理程序——它可能远离抛出异常的地方。

此外，在异常发生时创建的任何本地对象都将被销毁。这种本地对象的自动清理通常被称为*栈展开*。T3】

此外，您可以投掷任意多种不同类型的对象。通常，您会为每一类错误抛出不同的类型。其思想是将信息存储在对象及其类的名称中，这样在调用上下文中的某个人就可以知道如何处理您的异常。

捕捉异常

如前所述，C++ 异常处理的优势之一是您可以在一个地方集中精力解决问题，然后在另一个地方处理代码中的错误。

try 块

如果你在一个函数中抛出了一个异常(或者一个被调用的函数抛出了一个异常)，那么这个函数就会因为抛出的异常而退出。如果你不想让一个`throw`离开一个函数，你可以在函数中设置一个特殊的块，在这里你可以尝试解决你实际的编程问题(并且可能产生异常)。这个块被称为 *try 块*,因为您在那里尝试各种函数调用。try 块是一个普通的作用域，前面有关键字`try`，如:

```cpp
try {
  // Code that may generate exceptions
}
```

如果通过仔细检查所用函数的返回代码来检查错误，则需要用设置和测试代码包围每个函数调用，即使多次调用同一个函数也是如此。使用异常处理，您将所有内容放在一个`try`块中，并在`try`块之后处理异常。因此，您的代码更容易编写和阅读，因为代码的目标不会与错误处理混淆。

异常处理程序

当然，抛出的异常必须在某个地方结束。这个地方就是*异常处理程序*，你需要一个异常处理程序来处理你想要捕捉的每一种异常类型。然而，多态也适用于异常，因此一个异常处理程序可以处理一个异常类型和从该类型派生的类。

异常处理程序紧跟在`try`块之后，由关键字`catch`表示，如:

```cpp
try {
  // Code that may generate exceptions
} catch(type1 id1) {
  // Handle exceptions of type1
} catch(type2 id2) {
  // Handle exceptions of type2
} catch(type3 id3)
  // Etc...
} catch(typeNidN)
  // Handle exceptions of typeN
}
// Normal execution resumes here...
```

`catch`子句的语法类似于接受单个参数的函数。标识符(`id1`、`id2`等等)可以在处理程序中使用，就像函数参数一样，尽管如果处理程序中不需要标识符，也可以省略它。异常类型通常给你足够的信息来处理它。

处理程序必须直接出现在`try`块之后。如果抛出异常，异常处理机制会寻找第一个参数与异常类型匹配的处理程序。然后它进入那个`catch`子句，异常被认为已经处理。(一旦找到了`catch`子句，对处理程序的搜索就会停止。)只执行匹配的`catch`子句；然后，控制在与该 try 块关联的最后一个处理程序之后继续。

注意，在`try`块中，许多不同的函数调用可能会生成相同类型的异常，但是您只需要一个处理程序。

为了说明`try`和`catch`,[清单 17-3](#list3) 修改了`Nonlocal.cpp` ( [清单 17-1](#list1) )，用`try`块替换了对`setjmp()`的调用，用`throw`语句替换了对`longjmp()`的调用。

***[清单 17-3](#_list3)*** 。图示试&抓块

```cpp
//: C17:Nonlocal2.cpp
// Illustrates exceptions.
#include <iostream>
using namespace std;
class Rainbow {
public:
  Rainbow() { cout << "Rainbow()" << endl; }
  ∼Rainbow() { cout << "∼Rainbow()" << endl; }
};
void oz() {
  Rainbow rb;
  for(int i = 0; i < 3; i++)
    cout << "there's no place like home" << endl;
  throw 47;
}
int main() {
  try {
    cout << "tornado, witch, munchkins..." << endl;
    oz();
  } catch(int) {
    cout << "Auntie Em! I had the strangest dream..."
         << endl;
  }
} ///:∼
```

当`oz()`中的`throw`语句执行时，程序控制返回，直到找到带`int`参数的`catch`子句。继续执行那个`catch`条款的主体。这个程序和`Nonlocal.cpp`最重要的区别是当`throw`语句导致执行离开函数`oz()`时，对象`rb`的析构函数被调用。

终止和恢复

异常处理理论中有两种基本模型:终止和恢复。在*终止*(这是 C++ 支持的)中，您假设错误非常严重，以至于没有办法从异常发生的地方自动恢复执行。换句话说，抛出异常的人决定没有办法挽回局面，他们不希望*回来。*

另一种错误处理模型被称为*恢复*，于 20 世纪 60 年代由 PL/I 语言首次引入。使用恢复语义意味着期望异常处理程序做一些事情来纠正这种情况，然后自动重试出错的代码，假设第二次成功。如果您想在 C++ 中恢复，您必须显式地将执行转移回发生错误的代码，通常是通过重复首先将您送到那里的函数调用。把你的`try`块放在一个`while`循环中是很常见的，这个循环不断地重新进入`try`块，直到结果令人满意。

从历史上看，使用支持恢复性异常处理的操作系统的程序员最终会使用类似终止的代码并跳过恢复。虽然恢复听起来很吸引人，但在实践中似乎并不那么有用。一个原因可能是异常和它的处理程序之间的距离。终止于远处的处理程序是一回事，但是跳到那个处理程序然后再跳回来对于大型系统来说可能在概念上太困难了，因为在大型系统中，异常是从许多点生成的。

异常匹配

当抛出一个异常时，异常处理系统会按照它们在源代码中出现的顺序检查“最近的”处理程序。当它找到一个匹配项时，该异常被视为已处理，不再进行进一步的搜索。

匹配异常并不要求异常和它的处理程序之间有完美的关联。对 derivedclass 对象的对象或引用将匹配基类的处理程序。(但是，如果处理程序是针对对象而不是引用的，则异常对象在传递给处理程序时会被“切片”，即被截断为基类型。这不会造成损害，但是会丢失所有派生类型的信息*。*)出于这个原因，也为了避免制作异常对象的另一个副本，通过*引用*而不是通过值来捕捉异常总是更好的。如果抛出指针，通常的标准指针转换用于匹配异常。但是，在匹配过程中，不会使用自动类型转换来将一种异常类型转换为另一种异常类型。例如，参见[清单 17-4](#list4) 。

***[清单 17-4](#_list4)*** 。说明异常匹配

```cpp
//: C17:Autoexcp.cpp
// No matching conversions.
#include <iostream>
using namespace std;
class Except1 {};
class Except2 {
public:
  Except2(const Except1&) {}
};
void f() { throw Except1(); }
int main() {
  try { f();
  } catch(Except2&) {
    cout << "inside catch(Except2)" << endl;
  } catch(Except1&) {
    cout << "inside catch(Except1)" << endl;
  }
} ///:∼
```

尽管您可能认为可以通过使用转换构造器将一个`Except1`对象转换成一个`Except2`来匹配第一个处理程序，但是系统不会在异常处理期间执行这样的转换，您将在`Except1`处理程序处结束。

清单 17-5 显示了一个基类处理程序如何捕捉一个派生类异常。

***[清单 17-5](#_list5)*** 。说明异常层次结构

```cpp
//: C17:Basexcpt.cpp
// Exception hierarchies.
#include <iostream>
using namespace std;
class X {
public:
  class Trouble {};
  class Small : public Trouble {};
  class Big : public Trouble {};
  void f() { throw Big(); }
};
int main() {
  X x;
  try {
    x.f();
  } catch(X::Trouble&) {
    cout << "caught Trouble" << endl;
  // Hidden by previous handler:
  } catch(X::Small&) {
    cout << "caught Small Trouble" << endl;
  } catch(X::Big&) {
    cout << "caught Big Trouble" << endl;
  }
} ///:∼
```

在这里，异常处理机制总是将一个`Trouble`对象、*或任何属于*、`Trouble`(通过公共继承、*)的对象匹配到第一个处理程序。这意味着第二个和第三个处理程序永远不会被调用，因为第一个处理程序捕获了它们。更有意义的做法是首先捕获派生类型，然后将基类型放在最后来捕获任何不太具体的类型。*

请注意，这些示例通过引用捕获异常，尽管对于这些类来说这并不重要，因为派生类中没有额外的成员，而且处理程序中也没有参数标识符。您通常希望在处理程序中使用引用参数而不是值参数，以避免切断信息。

捕捉任何异常

有时你想创建一个处理程序来捕捉任何类型的异常。使用参数列表中的省略号可以做到这一点，例如:

```cpp
catch(...) {
  cout << "an exception was thrown" << endl;
}
```

因为省略号会捕捉任何异常，所以您会希望将它放在处理程序列表的*末尾*以避免抢占它后面的任何异常。

省略号不能让你有一个参数，所以你不能知道任何关于异常或其类型的事情。这是一个无所不包的游戏；它通常用于清理一些资源，然后再抛出异常。

再次引发异常

当您有一些资源需要释放时，例如网络连接或需要释放的堆内存，您通常希望重新引发异常。

![image](img/sq.jpg) **注**详见本章后面的“资源管理”一节。

如果发生异常，您不必关心是什么错误导致了异常，您只需要关闭之前打开的连接。之后，您会希望让更接近用户的其他上下文(即，调用链中更高的位置)来处理异常。在这种情况下，省略号规范正是您想要的。您希望捕获任何异常，清理您的资源，然后重新抛出该异常以便在其他地方处理。您可以在处理程序中使用不带参数的`throw`来重新抛出异常，比如:

```cpp
catch(...) {
cout << "an exception was thrown" << endl;
// Deallocate your resource here, and then rethrow
  throw;
}
```

同一个`try`块的任何进一步的`catch`子句仍然被忽略——`throw`导致异常转到下一个更高上下文中的异常处理程序。此外，关于异常对象的一切都被保留下来，因此捕捉特定异常类型的更高上下文中的处理程序可以提取该对象可能包含的任何信息。

未捕获的异常

正如我在本章开始时解释的那样，异常处理被认为比传统的返回错误代码技术更好，因为异常不能被忽略，也因为错误处理逻辑与手头的问题是分离的。如果某个特定的`try`块之后的异常处理程序都不匹配某个异常，那么这个异常就会转移到下一个更高的上下文中，也就是说，没有捕捉到该异常的`try`块周围的函数或`try`块。(这个`try`块的位置乍一看并不总是很明显，因为它在调用链*中的位置更高。*)这个过程一直持续，直到在某个层次上，一个处理程序匹配到异常为止。此时，该异常被认为是“被捕获的”，不会进行进一步的搜索。

terminate()函数

如果任何级别的处理程序都没有捕捉到异常，则自动调用特殊库函数`terminate()`(在`<exception>`头文件中声明)。默认情况下，`terminate()`调用标准的 C 库函数`abort()`，它会突然退出程序。在 Unix 系统上，`abort()`也会导致核心转储。当调用`abort()`时，不会调用正常的程序终止函数，这意味着全局和静态对象的析构函数不会执行。如果局部对象的析构函数在堆栈展开时抛出异常(中断正在进行的异常*)，或者如果全局或静态对象的构造器或析构函数抛出异常，那么`terminate()`函数也会执行。(一般情况下*，*不允许析构函数抛出异常。)*

 *函数的作用是

您可以使用标准的`set_terminate()`函数安装您自己的`terminate()`函数，该函数返回一个指向您正在替换的`terminate()`函数的指针(这将是您第一次调用它时的默认库版本)，因此如果您愿意，您可以稍后恢复它。您的定制`terminate()`必须不带参数，并且有一个`void`返回值。此外，您安装的任何`terminate()`处理程序都不能返回或抛出异常，而是必须执行某种程序终止逻辑。如果调用`terminate()`，问题不可恢复。

[清单 17-6](#list6) 展示了`set_terminate()`的用法。在这里，返回值被保存和恢复，以便`terminate()`函数可以用来帮助隔离发生未捕获异常的代码部分。

***[清单 17-6](#_list6)*** 。使用 set _ termin ate()；此外，还演示了未捕获的异常

```cpp
//: C17:Terminator.cpp
// Use of set_terminate(). Also shows uncaught exceptions.
#include <exception>
#include <iostream>
using namespace std;
void terminator() {
  cout << "I'll be back!" << endl;
  exit(0);
}
void (*old_terminate)() = set_terminate(terminator);
class Botch {
public:
  class Fruit {};
  void f() {
    cout << "Botch::f()" << endl;
    throw Fruit();
  }
  ∼Botch() { throw 'c'; }
};
int main() {
  try {
    Botch b;
    b.f();
  } catch(...) {
    cout << "inside catch(...)" << endl;
  }
} ///:∼
```

起初，`old_terminate`的定义看起来有点混乱:它不仅创建了一个指向函数的指针，还将该指针初始化为`set_terminate()`的返回值。尽管您可能很熟悉在指向函数的声明后面看到分号，但这里它只是另一种变量，可以在定义时初始化。

类`Botch`不仅在`f()`内部抛出异常，还在其析构函数中抛出异常。这导致了对`terminate()`的调用，正如你在`main()`中看到的。即使异常处理程序说`catch(...)`，这似乎捕捉了一切，没有理由调用`terminate()`，但是`terminate()`还是被调用了。在清理堆栈上的对象以处理一个异常的过程中，调用了`Botch`析构函数，这会生成第二个异常，从而强制调用`terminate()`。因此，抛出异常或导致异常被抛出的析构函数通常是糟糕的设计或草率编码的标志。

清理

异常处理的神奇之处在于，您可以从正常的程序流跳到适当的异常处理程序中。但是，如果在抛出异常时没有进行适当的清理，那么这样做是没有用的。C++ 异常处理保证当你离开一个作用域时，该作用域中所有构造器已经完成的对象都会被调用它们的析构函数。

清单 17-7 展示了没有完成的构造器不会调用相关的析构函数。它还显示了在创建对象数组的过程中抛出异常时会发生什么。

***[清单 17-7](#_list7)*** 。演示异常不会清理不完整的对象

```cpp
//: C17:Cleanup.cpp
// Exceptions clean up complete objects only.
#include <iostream>
using namespace std;
class Trace {
  static int counter;
  int objid;
public:
  Trace() {
    objid = counter++;
    cout << "constructing Trace #" << objid << endl;
    if(objid == 3) throw 3;
  }
  ∼Trace() {
    cout << "destructing Trace #" << objid << endl;
  }
};
int Trace::counter = 0;
int main() {
  try {
    Trace n1;
    // Throws exception:
    Trace array[5];
    Trace n2;  // Won't get here.
  } catch(int i) {
    cout << "caught " << i << endl;
  }
} ///:∼
```

类`Trace`跟踪对象，这样你就可以跟踪程序进度。它记录用数据成员`counter`创建的对象的数量，并用`objid`跟踪特定对象的数量。

主程序创建一个单独的对象，`n1` ( `objid` 0)，然后尝试创建一个由五个`Trace`对象组成的数组，但是在第四个对象(#3)完全创建之前抛出了一个异常。对象`n2`从未被创建。你可以在程序的输出中看到结果:

```cpp
constructing Trace #0
constructing Trace #1
constructing Trace #2
constructing Trace #3
destructing Trace #2
destructing Trace #1
destructing Trace #0
caught 3
```

成功创建了三个数组元素，但是在第四个元素的构造器中，引发了一个异常。因为`main()`中对`array[2]`的第四次构造永远不会完成，所以只调用对象`array[1]`和`array[0]`的析构函数。最后，对象`n1`被销毁，但不是对象`n2`，因为它从未被创建过。

资源管理

当编写带有异常的代码时，特别重要的是，您总是问:“如果发生异常，我的资源会被适当地清理吗？”大多数时候你是相当安全的，但是在构造器中有一个特殊的问题:如果一个异常在构造器完成之前被抛出，相关的析构函数将不会被调用。因此，在编写构造器时，你必须特别勤奋。

困难在于在构造器中分配资源。如果构造器中出现异常，析构函数就没有机会释放资源。这个问题最常发生在“*裸*指针上。我称它们为“*裸体”*指针是有道理的。他们的行为就像一个人脱下衣服开始洗澡，但洗完澡后不得不赤身裸体地出来，因为有人拿着他的衣服跑了。因此，在脱下他的衣服后，一个例外发生了，他的衣服被偷了，现在他不得不裸体出来，因为他对这种例外情况没有准备。代码示例见[清单 17-8](#list8) 。

***[清单 17-8](#_list8)*** 。演示了裸指针的情况

```cpp
//: C17:Rawp.cpp
// Naked pointers.
#include <iostream>
#include <cstddef>
using namespace std;
class Cat {
public:
  Cat() { cout << "Cat()" << endl; }
  ∼Cat() { cout << "∼Cat()" << endl; }
};
class Dog {
public:
  void* operator new(size_tsz) {
    cout << "allocating a Dog" << endl;
    throw 47;
  }
  void operator delete(void* p) {
    cout << "deallocating a Dog" << endl;
    ::operator delete(p);
  }
};
class UseResources {
  Cat* bp;
  Dog* op;
public:
  UseResources(int count = 1) {
    cout << "UseResources()" << endl;
    bp = new Cat[count];
    op = new Dog;
  }
  ∼UseResources() {
    cout << "∼UseResources()" << endl;
    delete [] bp; // Array delete
    delete op;
  }
};
int main() {
  try {
    UseResources ur(3);
  } catch(int) {
    cout << "inside handler" << endl;
  }
} ///:∼
```

输出是

```cpp
UseResources()
Cat()
Cat()
Cat()
allocating a Dog
inside handler
```

进入`UseResources`构造器，三个数组对象的`Cat`构造器成功完成。然而，在`Dog::operator new()`内部，会抛出一个异常(模拟内存不足的错误)。突然，你在处理程序中结束，*没有调用*析构函数。这是正确的，因为`UseResources`构造器无法完成，但这也意味着在堆上成功创建的`Cat`对象从未被销毁。

让一切都成为物体

为了防止这种资源泄漏，您必须以两种方式中的一种来防止这些“原始”资源分配(出于与上面相同的原因，我将它们称为*原始资源分配*)。他们表现得像一个“原始”的人，有衣服(T2 资源)，但*没有做好充分准备*，以应对洗澡时有人带着他的衣服(T6 资源)逃跑的特殊情况，最终不得不赤身裸体地出来。

*   您可以在构造器中捕获异常，然后释放资源。
*   可以将分配放在对象的构造器中，将释放放在对象的析构函数中。

使用后一种方法，由于是本地对象生命周期的一部分，每个分配都变成了原子的，如果它失败了，其他资源分配对象在栈展开期间被适当地清除。这种技术被称为资源获取是初始化(简称 RAII)，因为它将资源控制等同于对象生存期。使用模板是修改[清单 17-8](#list8) 以获得[清单 17-9](#list9) 中所示代码的一个极好的方法。

***[清单 17-9](#_list9)*** 。使用 RAII 说明了安全原子指针&

```cpp
//: C17:Wrapped.cpp
// Safe, atomic pointers.
#include <iostream>
#include <cstddef>
using namespace std;
// Simplified. Yours may have other arguments.
template<class T, int sz = 1> class PWrap {
  T* ptr;
public:
  class RangeError {}; // Exception class
  PWrap() {
    ptr = new T[sz];
    cout << "PWrap constructor" << endl;
  }
  ∼PWrap() {
    delete[] ptr;
    cout << "PWrap destructor" << endl;
  }
  T& operator[](int i) throw(RangeError) {
    if(i >= 0 && i < sz) return ptr[i];
    throw RangeError();
  }
};
class Cat {
public:
  Cat() { cout << "Cat()" << endl; }
  ∼Cat() { cout << "∼Cat()" << endl; }
  void g() {}
};
class Dog {
public:
  void* operator new[](size_t) {
    cout << "Allocating a Dog" << endl;
    throw 47;
  }
  void operator delete[](void* p) {
    cout << "Deallocating a Dog" << endl;
    ::operator delete[](p);
  }
};
class UseResources {
  PWrap<Cat, 3> cats;
  PWrap<Dog> dog;
public:
  UseResources() { cout << "UseResources()" << endl; }
  ∼UseResources() { cout << "∼UseResources()" << endl; }
  void f() { cats[1].g(); }
};
int main() {
  try {
    UseResources ur;
  } catch(int) {
    cout << "inside handler" << endl;
  } catch(...) {
    cout << "inside catch(...)" << endl;
  }
} ///:∼
```

不同之处在于使用了模板来包装指针并使它们成为对象。这些对象的构造器在`UseResources`构造器的主体之前被调用*，并且在抛出异常之前完成的这些构造器中的任何一个都将在栈展开期间调用它们相关的析构函数。*

`PWrap`模板展示了异常的一个更典型的用法:如果参数超出范围，就会创建一个名为`RangeError`的嵌套类在`operator[ ]`中使用。因为`operator[ ]`返回一个引用，所以不能返回零。

![image](img/sq.jpg) **注意**没有空引用。

这是一个真正的异常情况——您不知道在当前上下文中该做什么，并且您不能返回一个不可能的值。在[清单 17-9](#list9) 中，`RangeError` [5]很简单，假设所有必要的信息都在类名中，但是如果有用的话，你可能还想添加一个包含索引值的成员。

现在输出是

```cpp
Cat()
Cat()
Cat()
PWrap constructor
allocating a Dog
∼Cat()
∼Cat()
∼Cat()
PWrap destructor
inside handler
```

再次，`Dog`的存储分配抛出了一个异常，但是这次`Cat`对象的数组被正确地清理了，所以没有内存泄漏。

使用自动指针

由于动态内存是典型 C++ 程序中使用最频繁的资源，该标准为指向堆内存的指针提供了一个 RAII 包装器，可以自动释放内存。在`<memory>`头中定义的`auto_ptr`类模板有一个构造器，该构造器接受一个指向其泛型类型的指针(无论您在代码中使用什么)。`auto_ptr`类模板还重载了指针操作符`*`和`->`，将这些操作转发给`auto_ptr`对象持有的原始指针。因此您可以像使用原始指针一样使用`auto_ptr`对象。清单 17-10 显示了它是如何工作的。

***[清单 17-10](#_list10)*** 。演示 auto_ptr 的 RAII 特性

```cpp
//: C17:Auto_ptr.cpp
// Illustrates the RAII nature of auto_ptr.
#include <memory>
#include <iostream>
#include <cstddef>
using namespace std;
class TraceHeap {
  int i;
public:
  static void* operator new(size_t siz) {
    void* p = ::operator new(siz);
    cout << "Allocating TraceHeap object on the heap "
         << "at address " << p << endl;
    return p;
  }
  static void operator delete(void* p) {
    cout << "Deleting TraceHeap object at address "
         << p << endl;
    ::operator delete(p);
  }
  TraceHeap(int i) : i(i) {}
  intgetVal() const { return i; }
};
int main() {
  auto_ptr<TraceHeap> pMyObject(new TraceHeap(5));
  cout << pMyObject->getVal() << endl;  // Prints 5
} ///:∼
```

`TraceHeap`类重载了`operator new`和`operator delete`，这样你就可以清楚地看到发生了什么。注意，像任何其他类模板一样，您要在模板参数中指定要使用的类型。你没有说`TraceHeap*`，但是——`auto_ptr`已经知道它将存储一个指向你的类型的指针。`main()`的第二行验证了`auto_ptr`的`operator->()`函数对原始的底层指针应用了间接寻址。最重要的是，即使您没有显式删除原始指针，`pMyObject`的析构函数也会在堆栈展开期间删除原始指针，如以下输出所示:

```cpp
Allocating TraceHeap object on the heap at address 8930040
5
Deleting TraceHeap object at address 8930040
```

对于指针数据成员，类模板也很方便。因为由值包含的类对象总是被析构，`auto_ptr`成员总是在包含对象被析构时删除它们包装的原始指针。

函数级 try 块

由于构造器通常会引发异常，所以您可能希望处理在初始化对象的成员或基子对象时发生的异常。为此，您可以将这些子对象的初始化放在一个*函数级的 try 块*中。与通常的语法不同，构造器初始化器的`try`块是构造器体，相关的`catch`块跟在构造器体后面，如[清单 17-11](#list11) 所示。

***[清单 17-11](#_list11)*** 。阐释如何处理子对象的异常

```cpp
//: C17:InitExcept.cpp {-bor}
// Handles exceptions from subobjects.
#include <iostream>
using namespace std;
 class Base {
  int i;
public:
  classBaseExcept {};
  Base(int i) : i(i) { throw BaseExcept(); }
};
class Derived : public Base {
public:
  class DerivedExcept {
    const char* msg;
  public:
    DerivedExcept(const char* msg) : msg(msg) {}
    const char* what() const { return msg; }
  };
  Derived(int j) try : Base(j) {
    // Constructor body
    cout << "This won't print" << endl;
  } catch(BaseExcept&) {
    throw DerivedExcept("Base subobject threw");;
  }
};
int main() {
  try {
    Derived d(3);
  } catch(Derived::DerivedExcept& d) {
    cout << d.what() << endl;  // "Base subobject threw"
  }
} ///:∼
```

请注意，`Derived`的构造器中的初始化列表位于`try`关键字之后，构造器体之前。如果发生异常，所包含的对象不会被构造，因此返回到创建它的代码是没有意义的。出于这个原因，唯一明智的做法是在函数级`catch`子句中抛出一个异常。

尽管不是特别有用，C++ 也允许函数级的块用于任何 T2 函数，如清单 17-12 T4 所示。

***[清单 17-12](#_list12)*** 。演示函数级 try 块

```cpp
//: C17:FunctionTryBlock.cpp {-bor}
// Function-level try blocks.
// {RunByHand} (Don’t run automatically by the makefile)
#include <iostream>
using namespace std;

int main() try {
  throw "main";
} catch(const char* msg) {
cout << msg << endl;
return 1;
} ///:∼
```

在这种情况下，`catch`块可以以函数体正常返回的方式返回。使用这种类型的函数级`try`块与在函数体内的代码周围插入一个`try-catch`没有太大区别。

标准例外

标准 C++ 库使用的异常也可供您使用。一般来说，从一个标准的异常类开始比试图定义自己的异常类更容易、更快。如果标准类不能完全满足您的需求，您可以从它派生。

所有标准的异常类最终都是从头文件`<exception>`中定义的类`exception`中派生出来的。两个主要的派生类是`logic_error`和`runtime_error`，它们位于`<stdexcept>`(它本身包括`<exception>`)。类`logic_error`表示编程逻辑中的错误，比如传递了一个无效的参数。运行时错误是由于硬件故障或内存耗尽等不可预见的因素导致的。`runtime_error`和`logic_error`都提供了一个接受`std::string`参数的构造器，这样你就可以在异常对象中存储一条消息，然后用`exception::what()`提取它，如[清单 17-13](#list13) 所示。

***[清单 17-13](#_list13)*** 。演示如何派生异常类

```cpp
//: C17:StdExcept.cpp
// Derives an exception class from std::runtime_error.
#include <stdexcept>
#include <iostream>
using namespace std;

class MyError : public runtime_error {
public:
  MyError(const string& msg = "") : runtime_error(msg) {}
};
int main() {
  try {
    throw MyError("my message");
  } catch(MyError& x) {
    cout << x.what() << endl;
  }
} ///:∼
```

尽管`runtime_error`构造器将消息插入到它的`std::exception`子对象中，`std::exception`没有提供接受`std::string`参数的构造器。你通常想从`runtime_error`或者`logic_error`(或者*它们的一个派生物*)中派生出你的异常类，而不是从`std::exception`中。

表 17-1 描述了标准异常类别。

[表 17-1。](#_Tab1)标准异常类

| `exception` | C++ 标准库引发的所有异常的基类。您可以询问 what()并检索初始化异常时使用的可选字符串。 |
| `logic_error` | 源自`exception`。报告程序逻辑错误，这些错误大概可以通过检查发现。 |
| `runtime_error` | 源自`exception`。报告运行时错误，这些错误可能只有在程序执行时才能被检测到。 |

iostream 异常类`ios::failure`也是从`exception`派生的，但是它没有进一步的子类。

您可以按原样使用下面两个表中的类，也可以将它们用作基类，从基类派生您自己的更具体类型的异常。参见[表 17-2](#Tab2) 和 [17-3](#Tab3) 。

[表 17-2。](#_Tab2)从标准异常类派生的异常类 logic_error

| 从`logic_error`派生的异常类 |
| --- |
| `domain_error` | 报告违反前提条件的情况。 |
| `invalid_argument` | 指示引发它的函数的无效参数。 |
| `length_error` | 表示试图生成一个长度大于或等于`npos`(上下文大小类型的最大可表示值，通常为`std::size_t`)的对象。 |
| `out_of_range` | 报告超出范围的参数。 |
| `bad_cast` | 在运行时类型识别中执行无效的`dynamic_cast`表达式时抛出(见[第 8 章](08.html))。 |
| `bad_typeid` | 在表达式`typeid(*p)`中报告空指针`p`。(再次，运行时类型识别特征；参见[第二十章](20.html)。 |

[表 17-3。](#_Tab3)从标准异常类派生的异常类- runtime_error

| 从`runtime_error`派生的异常类 |
| --- |
| `range_error` | 报告违反发布条件的情况。 |
| `overflow_error` | 报告算术溢出。 |
| `bad_alloc` | 报告分配存储失败。 |

异常规格

你不需要通知使用你的函数的人你可能抛出什么异常。然而，不这样做可以被认为是不文明的，因为这意味着用户不能确定应该编写什么代码来捕捉所有潜在的异常。如果他们有你的源代码，他们可以搜索并寻找`throw`语句，但是库通常没有源代码。好的文档可以帮助缓解这个问题，但是有多少软件项目是有良好文档记录的呢？C++ 提供了语法来告诉用户这个函数抛出的异常，这样用户就可以处理它们。这是可选的*异常规范*，它修饰一个函数的声明，出现在参数列表之后。

异常规范重用关键字`throw`，后面是函数可能抛出的所有类型的潜在异常的括号列表。您的函数声明可能如下所示:

```cpp
void f() throw(toobig, toosmall, divzero);
```

就异常而言，传统的函数声明

```cpp
void f();
```

意味着任何类型的异常都可以从函数中抛出。如果你说

```cpp
void f() throw();
```

这个函数不会抛出任何异常(所以你最好确保调用链中更靠下的函数不会让任何异常向上传播！).

为了良好的编码策略、良好的文档以及函数调用方的易用性，在编写抛出异常的函数时，可以考虑使用异常规范。

![image](img/sq.jpg) **注**本章稍后将讨论该指南的变体。

意外的()函数

如果你的异常规范声明你将抛出一组特定的异常，然后你抛出了不在那组中的东西，惩罚是什么？当您抛出异常规范中没有出现的内容时，会调用特殊函数`unexpected()`。如果发生这种不幸的情况，默认的`unexpected()`调用本章前面描述的`terminate()`函数。

函数的作用是

和`terminate()`一样，`unexpected()`机制会安装您自己的函数来响应意外的异常。你可以用一个名为`set_unexpected()`的函数来实现，这个函数和`set_terminate()`一样，接受一个没有参数和`void`返回值的函数的地址。此外，因为它返回`unexpected()`指针的前一个值，所以您可以保存它并在以后恢复它。要使用`set_unexpected()`，包括头文件`<exception>`。清单 17-14 显示了到目前为止本节所讨论的特性的一个简单用法。

***[清单 17-14](#_list14)*** 。使用异常规范&的意外()机制

```cpp
//: C17:Unexpected.cpp
// Exception specifications & unexpected(),
//{-msc} (Doesn’t terminate properly)
#include <exception>
#include <iostream>
using namespace std;
class Up {};
class Fit {};
void g();
void f(int i) throw(Up, Fit) {
  switch(i) {
    case 1: throw Up();
    case 2: throw Fit();
  }
  g();
}
// void g() {}                   // Version 1
void g() { throw 47; }           // Version 2
void my_unexpected() {
  cout << "unexpected exception thrown" << endl;
  exit(0);
}

int main() {
  set_unexpected(my_unexpected); // (Ignores return value)
  for(int i = 1; i <= 3; i++)
    try {
      f(i);
    } catch(Up) {
      cout << "Up caught" << endl;
    } catch(Fit) {
      cout << "Fit caught" << endl;
    }
} ///:∼
```

创建类`Up`和`Fit`只是为了抛出异常。异常类通常很小，但是它们肯定可以保存额外的信息，以便处理程序可以查询这些信息。

`f()`函数在其异常规范中承诺只抛出类型为`Up`和`Fit`的异常，从函数定义来看，这似乎是合理的。由`f()`调用的`g()`版本一不抛出任何异常，所以这是真的。但是如果有人更改了`g()`，使其抛出不同类型的异常(如本例中的第二个版本，它抛出了一个`int`)，那么就违反了`f()`的异常规范。

`my_unexpected()`函数没有参数或返回值，遵循自定义`unexpected()`函数的正确形式。它只是显示一条消息，这样您就可以看到它被调用了，然后退出程序(这里使用了`exit(0)`，这样书的`make`进程就不会中止)。您的新`unexpected()`函数不应该有`return`语句。

在`main()`中，`try`程序块在一个`for`循环中，所以所有的可能性都被执行了。这样就可以达到复盘之类的东西。将`try`模块嵌套在`for`、`while`、`do`或`if`中，并引发任何异常以尝试修复问题；然后再次尝试`try`块。

只有`Up`和`Fit`异常被捕获，因为这些是`f()`的程序员说会被抛出的唯一异常。`g()`的版本二导致`my_unexpected()`被调用，因为`f()`随后抛出一个`int`。

在对`set_unexpected()`的调用中，返回值被忽略，但是它也可以保存在指向函数的指针中，以后再恢复，就像本章前面的`set_terminate()`例子([清单 17-6](#list6) )一样。

典型的`unexpected`处理程序记录错误并通过调用`exit()`终止程序。然而，它可以抛出另一个异常(或者，重新抛出同一个异常)或者调用`abort()`。如果它抛出了一个异常，该异常是最初违反了规范的函数所允许的类型，那么搜索将在具有该异常规范的函数的*调用*处重新开始。

![image](img/sq.jpg) **注意**这种行为是`unexpected()`独有的。

如果从您的`unexpected`处理程序抛出的异常不被原始函数的规范所允许，就会发生两个事件之一。

1.  如果`std::bad_exception`(在`<exception>`中定义)在函数的异常规范中，从意外处理程序抛出的异常将被替换为一个`std::bad_exception`对象，搜索将像以前一样从函数中恢复。
2.  如果原始函数的规范不包括`std::bad_exception`，则调用`terminate()`。

清单 17-15 说明了这种行为。

***[清单 17-15](#_list15)*** 。列举了两个糟糕的例外情况

```cpp
//: C17:BadException.cpp {-bor}
#include <exception>    // For std::bad_exception
#include <iostream>
#include <cstdio>
using namespace std;
// Exception classes:
class A {};
class B {};

// terminate() handler
void my_thandler() {
  cout << "terminate called" << endl;
  exit(0);
}
// unexpected() handlers
void my_uhandler1() { throw A(); }
void my_uhandler2() { throw; }
// If we embed this throw statement in f or g,
// the compiler detects the violation and reports
// an error, so we put it in its own function.
void t() { throw B(); }
void f() throw(A) { t(); }
void g() throw(A, bad_exception) { t(); }
int main() {
  set_terminate(my_thandler);
  set_unexpected(my_uhandler1);
  try {
    f();
  } catch(A&) {
    cout << "caught an A from f" << endl;
  }
  set_unexpected(my_uhandler2);
  try {
    g();
  } catch(bad_exception&) {
    cout << "caught a bad_exception from g" << endl;
  }
  try {
    f();
  } catch(...) {
    cout << "This will never print" << endl;
  }
} ///:∼
```

`my_uhandler1()`处理程序抛出一个可接受的异常(`A`)，所以在第一次捕捉成功时执行继续。`my_uhandler2()`处理程序没有抛出有效的异常(`B`，但是由于`g`指定了`bad_exception`，所以`B`异常被一个`bad_exception`对象替换，第二次捕捉也成功了。由于`f`的规范中不包含`bad_exception`，因此`my_thandler()`被作为终止处理程序调用。以下是输出结果:

```cpp
caught an A from f
caught a bad_exception from g
terminate called
```

更好的异常规范？

您可能会觉得现有的异常规范规则不太安全

```cpp
void f();
```

*应该是指这个函数没有抛出异常。如果程序员想抛出任何类型的异常，你可能会认为他或她*应该*说*

```cpp
void f() throw(...); // Not in C++
```

这肯定是一种改进，因为函数声明会更加明确。不幸的是，通过查看函数中的代码，您并不总能知道是否会抛出异常——例如，它可能是因为内存分配而发生的。更糟糕的是，在异常处理被引入到语言中之前编写的现有函数可能会发现自己无意中抛出了异常，因为它们调用的函数(可能会链接到新的抛出异常的版本中)。因此，在这种毫无信息的情况下

```cpp
void f();
```

意思是，“也许我会抛出一个异常；*也许我不会*。”这种模糊性对于避免阻碍代码进化是必要的。如果您想指定`f`不抛出异常，请使用空列表，如下所示:

```cpp
void f() throw();
```

异常规范和继承

类中的每个公共函数本质上都与用户形成了一个契约；如果您向它传递某些参数，它将执行某些操作和/或返回一个结果。同样的约定在派生类中也必须成立；否则，预计的*将会违反派生类和基类之间的*关系。由于异常规范在逻辑上是函数声明的一部分，它们也必须在继承层次结构中保持一致。例如，如果基类中的成员函数说它将只抛出类型为`A`的异常，那么派生类中该函数的重写不能将任何其他异常类型添加到规范列表中，因为这将破坏任何遵循基类接口的程序。然而，你可以指定*更少的*异常或者*根本没有*，因为这不需要用户做任何不同的事情。你也可以指定任何东西，在派生函数的规范中，用*代替`A`。清单 17-16 显示了一个例子。*

***[清单 17-16](#_list16)*** 。说明协方差(异常规范&继承)

```cpp
//: C17:Covariance.cpp {-xo}
// Should cause compile error. {-mwcc}{-msc}
#include <iostream>
using namespace std;
class Base {
public:
  class BaseException {};
  class DerivedException : public BaseException {};
  virtual void f() throw(DerivedException) {
    throw DerivedException();
  }
  virtual void g() throw(BaseException) {
    throw BaseException();
  }
};
class Derived : public Base {
public:
  void f() throw(BaseException) {
    throw BaseException();
  }
  virtual void g() throw(DerivedException) {
    throw DerivedException();
  }
}; ///:∼
```

编译器应该用一个错误(*或至少一个警告*)来标记`Derived::f()`的覆盖，因为它以一种违反`Base::f()`规范的方式改变了它的异常规范。`Derived::g()`的规格是可以接受的，因为`DerivedException`是-a `BaseException`(而不是相反)。你可以把`Base/Derived`和`BaseException/DerivedException`想象成平行的类层次结构；当你在`Derived`时，你可以用`DerivedException`替换异常规范和返回值中对`BaseException`的引用。这种行为被称为*协方差*(因为两组类一起沿着它们各自的层次向下变化)。

何时不使用异常规范

如果你仔细阅读整个标准 C++ 库的函数声明，你会发现没有一个异常规范出现在任何地方！虽然这看起来很奇怪，但这种不一致有一个很好的原因:库主要由模板组成，你永远不知道泛型类型或函数会做什么。例如，假设您正在开发一个通用的堆栈模板，并试图为您的 pop 函数附加一个异常规范，如下所示:

```cpp
T pop() throw(logic_error);
```

因为您预期的唯一错误是堆栈下溢，所以您可能认为指定一个`logic_error`或其他适当的异常类型是安全的。但是类型`T`的复制构造器可能会抛出一个异常。然后`unexpected()`会被调用，你的程序会终止。你不能做出无法支持的保证。如果您不知道可能会发生什么异常，就不要使用异常规范。这就是为什么组合标准 C++ 库主要部分的模板类不使用异常规范——它们在*文档*中指定它们知道的关于的*异常，剩下的交给你。异常规范主要针对非模板类。*

异常安全

标准 C++ 库包括了`stack`容器。您会注意到的一件事是，`pop()`成员函数的声明如下:

```cpp
void pop();
```

你可能会觉得奇怪，因为`pop()`没有返回值。相反，它只是移除堆栈顶部的元素。要检索上限值，在调用`pop()`之前先调用`top()`。这种行为有一个重要的原因，它与*异常安全*有关，这是库设计中的一个关键考虑因素。异常安全有不同的级别，但最重要的是——顾名思义——异常安全是关于面对异常时的正确语义。

假设你正在用一个动态数组实现一个堆栈(姑且称之为`data`和计数器整数`count`，你试着写`pop()`让它返回值。这种`pop()`的代码可能看起来像这样:

```cpp
template<class T> T stack<T>::pop() {
  if(count == 0)
    throw logic_error("stack underflow");
```

`else`

```cpp

    return data[--count];
}
```

如果最后一行中为返回值调用的复制构造器在值返回时抛出异常，会发生什么？弹出的元素因为异常而没有返回，然而`count`已经被递减，所以你想要的顶部元素永远丢失了！问题是这个函数试图同时做两件事:(1)返回值，和(2)改变堆栈的状态。最好将这两个动作分成两个独立的成员函数，这正是标准的`stack`类所做的。(换句话说，遵循*衔接*的设计惯例——每个功能都要做好*一件事*。)异常安全代码使对象保持一致的状态，不会泄漏资源。

您还需要小心编写自定义赋值操作符。在第 12 章中，你看到`operator=`应该遵循以下模式。

1.  确保您没有分配给 self。如果是，请转到步骤 6。(*这是严格意义上的优化*。)
2.  分配指针数据成员所需的新内存。
3.  将数据从旧内存复制到新内存。
4.  删除旧的记忆。
5.  通过将新的堆指针分配给指针数据成员来更新对象的状态。
6.  返回`*this`。

重要的是，在所有新的部分都被安全地分配和初始化之前，不要改变对象的状态。一个好的技巧是将步骤 2 和 3 移到一个单独的函数中，通常称为`clone()`。[清单 17-17](#list17) 为一个有两个指针成员`theString`和`theInts`的类这样做。

***[清单 17-17](#_list17)*** 。阐释异常安全运算符(=)

```cpp
//: C17:SafeAssign.cpp
// An Exception-safe operator=.
#include <iostream>
#include <new>       // For std::bad_alloc
#include <cstring>
#include <cstddef>
using namespace std;
// A class that has two pointer members using the heap
class HasPointers {
  // A Handle class to hold the data
  struct MyData {
    const char* theString;
    const int* theInts;
    size_t numInts;
    MyData(const char* pString, const int* pInts,
      size_t nInts)
    : theString(pString), theInts(pInts), numInts(nInts) {}
  } *theData;        // The handle
  // Clone and cleanup functions:
  static MyData* clone(const char* otherString,
      const int* otherInts, size_t nInts) {
    char* newChars = new char[strlen(otherString)+1];
    int* newInts;
    try {
      newInts = new int[nInts];
    } catch(bad_alloc&) {
      delete [] newChars;
      throw;
    }
    try {
      // This example uses built-in types, so it won't
      // throw, but for class types it could throw, so we
      // use a try block for illustration. (This is the
      // point of the example!)
      strcpy(newChars, otherString);
      for(size_t i = 0; i < nInts; ++i)
        newInts[i] = otherInts[i];
    } catch(...) {
      delete [] newInts;
      delete [] newChars;
      throw;
    }
    return new MyData(newChars, newInts, nInts);
  }
  static MyData* clone(const MyData* otherData) {
    return clone(otherData->theString, otherData->theInts,
                 otherData->numInts);
  }
  static void cleanup(const MyData* theData) {
    delete [] theData->theString;
    delete [] theData->theInts;
    delete theData;
  }
public:
  HasPointers(const char* someString, constint* someInts,
              size_t numInts) {
    theData = clone(someString, someInts, numInts);
  }
  HasPointers(const HasPointers& source) {
    theData = clone(source.theData);
  }
  HasPointers& operator=(const HasPointers& rhs) {
    if(this != &rhs) {
      MyData* newData = clone(rhs.theData->theString,
        rhs.theData->theInts, rhs.theData->numInts);
      cleanup(theData);
      theData = newData;
    }
    return *this;
  }
  ∼HasPointers() { cleanup(theData); }
  friend ostream&
  operator<<(ostream& os, const HasPointers& obj) {
    os << obj.theData->theString << ": ";
    for(size_t i = 0; i < obj.theData->numInts; ++i)
      os << obj.theData->theInts[i] << ' ';
    return os;
  }
};
int main() {
  int someNums[] = { 1, 2, 3, 4 };
  size_t someCount = sizeof someNums / sizeof someNums[0];
  int someMoreNums[] = { 5, 6, 7 };
  size_t someMoreCount =
  sizeof someMoreNums / sizeof someMoreNums[0];
  HasPointers h1("Hello", someNums, someCount);
  HasPointers h2("Goodbye", someMoreNums, someMoreCount);
  cout << h1 << endl;  // Hello: 1 2 3 4
  h1 = h2;
  cout << h1 << endl;  // Goodbye: 5 6 7
} ///:∼
```

为了方便起见，`HasPointers`使用`MyData`类作为两个指针的句柄。每当需要分配更多内存时，无论是在构造还是赋值期间，最终都会调用第一个`clone`函数来完成这项工作。如果第一次调用`new`操作符时内存失败，就会自动抛出一个`bad_alloc`异常。如果它发生在第二次分配时(对于`theInts`，你必须为`theString`清理内存——因此第一个`try`块捕捉到一个`bad_alloc`异常。第二个`try`块在这里并不重要，因为你只是复制了`int`和指针(所以不会发生异常)，但是每当你复制对象时，它们的赋值操作符可能会导致异常，所以一切都需要清理。在两个异常处理程序中，请注意您*重新抛出了*异常*和*。那是因为你只是在这里管理资源；用户仍然需要知道出错了，所以您让异常沿着动态链向上传播。不默默吞下异常的软件库被称为*异常中立*。总是努力编写既异常安全又异常中立的库。

如果您仔细检查前面的代码，您会注意到没有一个`delete`操作会抛出异常。这个代码取决于这个事实。回想一下，当您在一个对象上调用`delete`时，该对象的析构函数被调用。事实证明，如果不假设析构函数不抛出异常，设计异常安全的代码几乎是不可能的。不要让析构函数抛出异常。

注意在本章结束之前，我们将再次提醒你这一点。

异常编程

对于大多数程序员，尤其是 C 程序员，异常在他们现有的语言中是不可用的，需要一些调整。以下是异常编程的指导原则。

何时避免例外

例外不是所有问题的答案；过度使用会带来麻烦。以下章节指出了*未*授权的例外情况。决定何时使用异常的最佳建议是，只有当函数不符合其规范时才抛出异常。

不适用于异步事件

标准 C `signal()`系统和任何类似的系统都处理异步事件——发生在程序流程之外的事件，也就是程序无法预料的事件。您不能使用 C++ 异常来处理异步事件，因为异常及其处理程序在同一个调用堆栈上。也就是说，异常依赖于程序运行时堆栈上函数调用的动态链(它们有*动态范围*，而异步事件必须由完全独立的代码处理，这些代码不是正常程序流的一部分(通常是中断服务例程或事件循环)。不要从中断处理程序抛出异常。

这并不是说异步事件不能与异常相关联。但是中断处理程序应该尽可能快地完成它的工作，然后返回。处理这种情况的典型方法是在中断处理程序中设置一个标志，并在主线代码中同步检查它。

不适用于良性错误情况

如果您有足够的信息来处理一个错误，它就不是一个异常。在当前的上下文中处理它，而不是在更大的上下文中抛出一个异常。

此外，对于机器级别的事件，如被零除，不会引发 C++ 异常。我们假设一些其他的机制，比如操作系统或者硬件，来处理这些事件。通过这种方式，C++ 异常可以相当有效，并且它们的使用仅限于程序级的异常情况。

不用于控制流

异常看起来有点像替代返回机制，又有点像`switch`语句，所以您可能会尝试使用异常来代替这些普通的语言机制。这是一个坏主意，部分原因是异常处理系统的效率明显低于正常的程序执行。异常是一种罕见的事件，所以正常的程序不应该支付它们。此外，除了错误条件之外的任何异常都很容易让类或函数的用户感到困惑。

您不必被迫使用异常

有些程序非常简单(例如，小工具)。您可能只需要接受输入并执行一些处理。在这些程序中，您可能会尝试分配内存但失败，尝试打开文件但失败，等等。在这些程序中，显示一条消息并退出程序是可以接受的，让系统来收拾残局，而不是自己努力捕捉所有异常并恢复所有资源。基本上，如果你不需要异常，你不会被迫使用它们。

新异常，旧代码

出现的另一种情况是修改不使用异常的现有程序。你可能会引入一个*使用了*异常的库，并且想知道你是否需要修改整个程序中的所有代码。假设您已经有了一个可接受的错误处理方案，最简单的方法就是将使用新库的最大的代码块包围起来(这可能是用一个`try`代码块、*后跟一个* `catch(...)`和基本错误消息来包围`main()`中的所有代码)。您可以通过添加更具体的处理程序来将它细化到任何必要的程度，但是，在任何情况下，您必须添加的代码都可以是最少的。更好的做法是将您的异常生成代码隔离在一个`try`块中，并编写处理程序将异常转换成您现有的错误处理方案。

当你创建一个供其他人使用的库时，考虑异常是非常重要的，尤其是当你不知道他们需要如何响应关键的错误条件时。

![image](img/sq.jpg) **注**回想一下前面关于异常安全以及为什么标准 C++ 库中没有异常规范的讨论。

异常的典型用法

务必使用异常来执行以下操作:

*   请修复该问题，然后重试导致异常的函数。
*   修补东西并继续，不要重试该功能。
*   在当前上下文中尽你所能，将*相同的*异常重新抛出到更高的上下文中。
*   在当前上下文中做你能做的任何事情，并向更高的上下文抛出一个*不同的*异常。
*   终止程序。
*   包装使用普通错误方案的函数(尤其是 C 库函数),这样它们反而会产生异常。
*   简化。如果你的错误处理方案让事情变得更复杂，那么使用起来会很痛苦，很烦人。异常可以用来使错误处理更简单、更有效。
*   使您的库和程序更加安全。这是一项短期投资(用于调试)，也是一项长期投资(用于应用程序健壮性)。

何时使用异常规范

异常规范就像一个函数原型:它告诉用户编写异常处理代码以及处理什么异常。它告诉编译器这个函数可能产生的异常，这样它就可以在运行时检测到违规。

您不能总是查看代码并预测特定函数会引发哪些异常。有时，它调用的函数会产生一个意外的异常，有时，一个没有抛出异常的旧函数会被一个抛出异常的新函数所替换，这样您就会得到一个对`unexpected()`的调用。任何时候使用异常规范或调用使用异常规范的函数时，都要考虑创建自己的`unexpected()`函数，记录一条消息，然后抛出异常或中止程序。

如前所述，您应该避免在模板类中使用异常规范，因为您无法预料模板参数类可能会抛出什么类型的异常。

从标准异常开始

在创建自己的异常之前，先检查一下标准的 C++ 库异常。如果一个标准的异常满足了你的需要，那么你的用户就很容易理解和处理它。

如果您想要的异常类型不是标准 C++ 库的一部分，请尝试从现有的标准异常中继承一个。如果你的用户总是能够编写他们的代码来期望在`exception()`类接口中定义的`what()`函数，那就太好了。

嵌套您自己的异常

如果您为您的特定类创建异常，最好将异常类嵌套在您的类中或包含您的类的命名空间中，以便向读者提供一个明确的消息，即该异常仅适用于您的类。此外，它还防止了全局名称空间的污染。即使您是从 C++ 标准异常派生的，您也可以嵌套您的异常。

使用异常层次结构

使用异常层次结构是对您的类或库可能遇到的严重错误类型进行分类的一种有价值的方法。这为用户提供了有用的信息，帮助他们组织代码，并为他们提供了忽略所有特定类型的异常并只捕捉基类类型的选项。此外，以后通过从同一基类继承而添加的任何异常都不会强制重写所有现有代码——基类处理程序将捕获新的异常。

标准 C++ 异常是异常层次结构的一个很好的例子。如果可能的话，在它的基础上构建您的异常。

多重继承(MI)

正如你将在[第 21 章](21.html)中读到的，MI 的唯一*本质*地方是如果你需要将一个对象指针向上转换到两个不同的基类——也就是说，如果你需要这两个基类的多态行为。原来，异常层次结构是多重继承的有用位置，因为多重继承异常类的任何根的基类处理程序都可以处理异常。

通过引用捕获，而不是通过值

正如您在“异常匹配”一节中看到的，您应该通过引用来捕捉异常，原因有两个:

*   以避免在将异常对象传递给处理程序时对其进行不必要的复制。
*   在捕获作为基类对象的派生异常时避免对象切片。

虽然您也可以抛出和捕捉指针，但这样做会引入更多的耦合——抛出者和捕捉者必须就如何分配和清理异常对象达成一致。这是一个问题，因为异常本身可能是由堆耗尽引起的。如果抛出异常对象，异常处理系统会处理所有存储。

在构造器中抛出异常

因为构造器没有返回值，所以之前你有两种方法在构造过程中报告错误:

*   设置一个非本地标志，并希望用户检查它。
*   返回一个创建不完整的对象，并希望用户检查它。

这个问题很严重，因为 C 程序员期望对象创建总是成功的，这在 C 中不是不合理的，因为类型是如此原始。但是在 C++ 程序中，构造失败后继续执行肯定是一场灾难，所以构造器是抛出异常的最重要的地方之一——现在您有了一种安全有效的方法来处理构造器错误。但是，您还必须注意对象内部的指针，以及在构造器内部引发异常时进行清理的方式。

不要在析构函数中引发异常

因为析构函数是在抛出其他异常的过程中被调用的，所以您绝不会想要在析构函数中抛出一个异常，或者通过在析构函数中执行的某些操作引发另一个异常。如果发生这种情况，在到达现有异常的 catch-clause 之前，可能会抛出一个新的异常*，这将导致对`terminate()`的调用。*

如果在析构函数中调用任何可能抛出异常的函数，这些调用应该在析构函数的`try`块中，并且析构函数必须自己处理所有异常。任何人都不能从析构函数中逃脱。

避免裸指针

参见[清单 17-9](#list9) 中的`Wrapped.cpp`。如果为指针分配了资源，那么裸指针通常意味着构造器中存在漏洞。指针没有析构函数，所以如果在构造器中抛出异常，这些资源不会被释放。对引用堆内存的指针使用`auto_ptr`或其他智能指针类型。

开销

当抛出异常时，会有相当大的运行时开销(但是这是很好的开销，因为对象是自动清理的！).出于这个原因，无论异常看起来多么诱人和聪明，您都不应该将它作为正常控制流的一部分。

异常应该很少发生，所以开销堆积在异常上，而不是正常执行的代码上。异常处理的一个重要设计目标是，当不使用*时，它可以在不影响执行速度的情况下实现；也就是说，只要您不抛出异常，您的代码就会像没有异常处理时一样快。这是否正确取决于您使用的特定编译器实现。*

![image](img/sq.jpg) **注**参见本节后面对“零成本模式”的描述。

您可以将一个`throw`表达式想象成对一个特殊系统函数的调用，该函数将异常对象作为一个参数，并沿着执行链向上回溯。为此，编译器需要将额外的信息放到堆栈中，以帮助展开堆栈。要理解这一点，您需要了解运行时堆栈。

每当调用一个函数时，关于该函数的信息就被推送到运行时堆栈中的一个*激活记录实例* ( *【阿里】* ) ，也称为*堆栈帧*。一个典型的堆栈帧包含调用函数的地址(这样执行可以返回给它)，一个指向函数的静态父函数的 ARI 的指针(这个范围在词法上包含被调用的函数，所以可以访问函数的全局变量)，一个指向调用它的函数(它的动态父函数)的指针。重复跟踪动态父链接的逻辑结果路径是本章前面提到的*动态链*或*调用链*。

这就是抛出异常时执行可以回溯的方式，这种机制使得在不了解彼此的情况下开发的组件可以在运行时交流错误。

为了启用异常处理的堆栈展开，需要为每个堆栈帧提供关于每个函数的额外异常相关信息。该信息描述了需要调用哪些析构函数(以便可以清理本地对象)，指示当前函数是否有一个`try`块，并列出相关联的 catch 子句可以处理哪些异常。

这些额外的信息会占用空间，所以支持异常处理的程序会比不支持异常处理的程序大一些。甚至使用异常处理的程序的编译时大小也更大，因为如何在运行时生成扩展堆栈帧的逻辑必须由编译器生成。

为了说明这一点，我在 Borland C++ Builder 和 Microsoft Visual C++ 中编译了有和没有异常处理支持的清单 17-18 中的程序。

***[清单 17-18](#_list18)*** 。说明有/没有异常处理支持的程序

```cpp
//: C17:HasDestructor.cpp {O}
*/* shows that programs with exception-handling support are bigger than those without */*
class HasDestructor {
public:
  ∼HasDestructor() {}
};
void g(); // For all we know, g may throw.
void f() {
  HasDestructor h;
  g();
} ///:∼
```

如果启用了异常处理，编译器必须在运行时为`f()`在 *ARI* 中保留关于`∼HasDestructor()`的可用信息(这样当`g()`抛出异常时，它可以正确地销毁`h`)。

[表 17-4](#Tab4) 根据编译的大小总结了编译的结果。obj)文件(字节)。

[表 17-4](#_Tab4) 。汇编流程结果(汇总)

| 编译器\模式 | 例外支持 | 无一例外的支持 |
| --- | --- | --- |
| `Borland` | Six hundred and sixteen | Two hundred and thirty-four |
| `Microsoft` | One thousand one hundred and sixty-two | Six hundred and eighty |

不要把两种模式的百分比差异看得太重。

请记住，异常(*应该是*)通常组合程序的一小部分，因此空间开销往往更小(通常在 5%到 15%之间)。

这种额外的内务处理会降低执行速度，但是聪明的编译器实现可以避免这种情况。由于关于异常处理代码和局部对象的偏移量的信息可以在编译时计算一次，所以这些信息可以保存在与每个函数相关联的单个位置，而不是保存在每个 ARI *中。*

从本质上消除了每个 ARI 的异常开销，从而避免了将它们压入堆栈的额外时间。这种方法被称为异常处理的*零成本模型*，前面提到的优化存储被称为*影子堆栈*。

审查会议

1.  错误恢复是你编写的每一个程序的基本关注点。在 C++ 中，当创建程序组件供他人使用时，这一点尤其重要。要创建一个*健壮的系统*，每个组件都必须健壮。
2.  C++ 中的*异常处理*的目标是使用比目前更少的代码来简化大型、可靠程序的创建，更确信你的应用程序没有未处理的错误。这是在很少或没有性能损失的情况下完成的，并且对现有代码的影响很小。
3.  基本的例外是*不太难学*；尽快在你的程序中使用它们。
4.  *异常*是那些*为你的项目提供直接和显著利益*的特性之一。*